Workbook
Name Slicer_Category: #N/A
Name Slicer_Product_Name: #N/A
Name Slicer_Region: #N/A
Name Slicer_Supplier1: #N/A

Sheet Product_Master
A1: Product_ID | B1: Product_Name | C1: Category | D1: Cost_Price | E1: Selling_Price
A2: P001 | B2: Choco Pie Popstick | C2: Snacks | D2: 46 | E2: 74 | G2: Row Labels | H2: cost price | I2: Selling Price
A3: P002 | B3: Kunafa Bites | C3: Premium | D3: 96 | E3: 146 | G3: Almond Crunch Bar | H3: 59 | I3: 90
A4: P003 | B4: Choco Crunch Cone | C4: Bars | D4: 66 | E4: 86 | G4: Berry Blast Chocolate | H4: 113 | I4: 168
A5: P004 | B5: Duo Choco Bites | C5: Bars | D5: 75 | E5: 99 | G5: Butterscotch Crunch Bar | H5: 54 | I5: 109
A6: P005 | B6: Choco Dip Cookie | C6: Premium | D6: 40 | E6: 98 | G6: Caramel Crunch Cubes | H6: 63 | I6: 158
A7: P006 | B7: Love Loaded Chocolate Bar | C7: Festive | D7: 42 | E7: 140 | G7: Cashew Delight Bites | H7: 76 | I7: 98
A8: P007 | B8: Choco Aura Custom Bar | C8: Premium | D8: 75 | E8: 128 | G8: Choco Aura Custom Bar | H8: 75 | I8: 128
A9: P008 | B9: Hazelnut Praline Chocolate | C9: Premium | D9: 46 | E9: 76 | G9: Choco Biscuit Pops | H9: 63 | I9: 113
A10: P009 | B10: Rose Pista Chocolate | C10: Festive | D10: 72 | E10: 96 | G10: Choco Crunch Cone | H10: 66 | I10: 86
A11: P010 | B11: Dry Fruit Special Chocolate | C11: Bars | D11: 94 | E11: 160 | G11: Choco Dip Cookie | H11: 40 | I11: 98
A12: P011 | B12: Almond Crunch Bar | C12: Bars | D12: 59 | E12: 90 | G12: Choco Fudge Squares | H12: 85 | I12: 130
A13: P012 | B13: Cashew Delight Bites | C13: Cookies | D13: 76 | E13: 98 | G13: Choco Lava Bites | H13: 78 | I13: 100
A14: P013 | B14: Pistachio Fusion Chocolate | C14: Cookies | D14: 101 | E14: 143 | G14: Choco Pie Popstick | H14: 46 | I14: 74
... A41: P040 | B41: Festive Chocolate Pack | C41: Festive | D41: 63 | E41: 145 | G41: Velvet Truffle Bites | H41: 106 | I41: 199
G42: White Chocolate Truffle | H42: 21 | I42: 95
G43: Grand Total | H43: 2644 | I43: 4754

Sheet Inventory
A1: Product_ID | B1: Product_Name | C1: Category | D1: Opening_Stock | E1: Stock_In | F1: Stock_Out | G1: Current_Stock | H1: Cost_Price | I1: Supplier | J1: inventory | K1: average inventory | L1: Turnover | M1: health | N1: value
A2: P006 | B2: Love Loaded Chocolate Bar | C2: Festive | D2: 172 | E2: 29 | F2: 144 | G2: 57 | H2: 42 | I2: Sweet Supplies | J2: =G2*H2 -> 2394 | K2: =D2+G2/2 -> 200.5 | L2: =F2/K2 -> 0.71820449 | M2: {=_xlfn.IFS(G2<50,"Low Stock",G2<100,"Medium Stock",G2>=100,"Healthy Stock")} -> Medium Stock | N2: =G2*H2 -> 2394
A3: P029 | B3: Choco Lava Bites | C3: Snacks | D3: 177 | E3: 96 | F3: 77 | G3: 196 | H3: 78 | I3: Global Cocoa | J3: =G3*H3 -> 15288 | K3: =D3+G3/2 -> 275 | L3: =F3/K3 -> 0.28 | M3: {=_xlfn.IFS(G3<50,"Low Stock",G3<100,"Medium Stock",G3>=100,"Healthy Stock")} -> Healthy Stock | N3: =G3*H3 -> 15288
A4: P014 | B4: Dark Fantasy Squares | C4: Snacks | D4: 180 | E4: 130 | F4: 165 | G4: 145 | H4: 20 | I4: Choco World | J4: =G4*H4 -> 2900 | K4: =D4+G4/2 -> 252.5 | L4: =F4/K4 -> 0.65346535 | M4: {=_xlfn.IFS(G4<50,"Low Stock",G4<100,"Medium Stock",G4>=100,"Healthy Stock")} -> Healthy Stock | N4: =G4*H4 -> 2900
A5: P038 | B5: Choco Biscuit Pops | C5: Premium | D5: 112 | E5: 126 | F5: 74 | G5: 164 | H5: 63 | I5: Global Cocoa | J5: =G5*H5 -> 10332 | K5: =D5+G5/2 -> 194 | L5: =F5/K5 -> 0.3814433 | M5: {=_xlfn.IFS(G5<50,"Low Stock",G5<100,"Medium Stock",G5>=100,"Healthy Stock")} -> Healthy Stock | N5: =G5*H5 -> 10332 | T5: Row Labels | U5: Count of Current_Stock
A6: P003 | B6: Choco Crunch Cone | C6: Bars | D6: 167 | E6: 69 | F6: 179 | G6: 57 | H6: 66 | I6: Choco World | J6: =G6*H6 -> 3762 | K6: =D6+G6/2 -> 195.5 | L6: =F6/K6 -> 0.91560102 | M6: {=_xlfn.IFS(G6<50,"Low Stock",G6<100,"Medium Stock",G6>=100,"Healthy Stock")} -> Medium Stock | N6: =G6*H6 -> 3762 | T6: Luxury Praline Box | U6: 4
A7: P038 | B7: Choco Biscuit Pops | C7: Premium | D7: 190 | E7: 107 | F7: 167 | G7: 130 | H7: 63 | I7: Global Cocoa | J7: =G7*H7 -> 8190 | K7: =D7+G7/2 -> 255 | L7: =F7/K7 -> 0.65490196 | M7: {=_xlfn.IFS(G7<50,"Low Stock",G7<100,"Medium Stock",G7>=100,"Healthy Stock")} -> Healthy Stock | N7: =G7*H7 -> 8190 | T7: Signature Cocoa Bars | U7: 4
A8: P006 | B8: Love Loaded Chocolate Bar | C8: Festive | D8: 112 | E8: 55 | F8: 74 | G8: 93 | H8: 42 | I8: ABC Traders | J8: =G8*H8 -> 3906 | K8: =D8+G8/2 -> 158.5 | L8: =F8/K8 -> 0.46687697 | M8: {=_xlfn.IFS(G8<50,"Low Stock",G8<100,"Medium Stock",G8>=100,"Healthy Stock")} -> Medium Stock | N8: =G8*H8 -> 3906 | T8: Pistachio Fusion Chocolate | U8: 4
A9: P014 | B9: Dark Fantasy Squares | C9: Snacks | D9: 199 | E9: 103 | F9: 93 | G9: 209 | H9: 20 | I9: ABC Traders | J9: =G9*H9 -> 4180 | K9: =D9+G9/2 -> 303.5 | L9: =F9/K9 -> 0.30642504 | M9: {=_xlfn.IFS(G9<50,"Low Stock",G9<100,"Medium Stock",G9>=100,"Healthy Stock")} -> Healthy Stock | N9: =G9*H9 -> 4180 | T9: Coconut Delight Bar | U9: 4
A10: P029 | B10: Choco Lava Bites | C10: Snacks | D10: 50 | E10: 32 | F10: 128 | G10: -46 | H10: 78 | I10: ABC Traders | J10: =G10*H10 -> -3588 | K10: =D10+G10/2 -> 27 | L10: =F10/K10 -> 4.7407407 | M10: {=_xlfn.IFS(G10<50,"Low Stock",G10<100,"Medium Stock",G10>=100,"Healthy Stock")} -> Low Stock | N10: =G10*H10 -> -3588 | T10: Fruit & Nut Chocolate | U10: 4
A11: P032 | B11: Choco Fudge Squares | C11: Premium | D11: 104 | E11: 134 | F11: 62 | G11: 176 | H11: 85 | I11: Global Cocoa | J11: =G11*H11 -> 14960 | K11: =D11+G11/2 -> 192 | L11: =F11/K11 -> 0.32291667 | M11: {=_xlfn.IFS(G11<50,"Low Stock",G11<100,"Medium Stock",G11>=100,"Healthy Stock")} -> Healthy Stock | N11: =G11*H11 -> 14960 | T11: Coffee Mocha Bites | U11: 4
A12: P040 | B12: Festive Chocolate Pack | C12: Festive | D12: 144 | E12: 137 | F12: 125 | G12: 156 | H12: 63 | I12: ABC Traders | J12: =G12*H12 -> 9828 | K12: =D12+G12/2 -> 222 | L12: =F12/K12 -> 0.56306306 | M12: {=_xlfn.IFS(G12<50,"Low Stock",G12<100,"Medium Stock",G12>=100,"Healthy Stock")} -> Healthy Stock | N12: =G12*H12 -> 9828 | Q12: Row Labels | R12: Count of Current_Stock | T12: Orange Zest Chocolate | U12: 4 | X12: Supplier | Y12: inventory value
A13: P037 | B13: Golden Caramel Bites | C13: Snacks | D13: 171 | E13: 63 | F13: 69 | G13: 165 | H13: 105 | I13: ABC Traders | J13: =G13*H13 -> 17325 | K13: =D13+G13/2 -> 253.5 | L13: =F13/K13 -> 0.27218935 | M13: {=_xlfn.IFS(G13<50,"Low Stock",G13<100,"Medium Stock",G13>=100,"Healthy Stock")} -> Healthy Stock | N13: =G13*H13 -> 17325 | Q13: Healthy Stock | R13: 101 | T13: Crunchy Wafer Chocolate | U13: 4 | X13: ABC Traders | Y13: 301534
A14: P027 | B14: Premium Cocoa Slabs | C14: Bars | D14: 67 | E14: 101 | F14: 77 | G14: 91 | H14: 92 | I14: Premium Foods | J14: =G14*H14 -> 8372 | K14: =D14+G14/2 -> 112.5 | L14: =F14/K14 -> 0.68444444 | M14: {=_xlfn.IFS(G14<50,"Low Stock",G14<100,"Medium Stock",G14>=100,"Healthy Stock")} -> Medium Stock | N14: =G14*H14 -> 8372 | Q14: Low Stock | R14: 46 | T14: Rose Pista Chocolate | U14: 4 | X14: Choco World | Y14: 227349
A15: P014 | B15: Dark Fantasy Squares | C15: Snacks | D15: 126 | E15: 115 | F15: 96 | G15: 145 | H15: 20 | I15: Sweet Supplies | J15: =G15*H15 -> 2900 | K15: =D15+G15/2 -> 198.5 | L15: =F15/K15 -> 0.4836272 | M15: {=_xlfn.IFS(G15<50,"Low Stock",G15<100,"Medium Stock",G15>=100,"Healthy Stock")} -> Healthy Stock | N15: =G15*H15 -> 2900 | Q15: Medium Stock | R15: 53 | T15: Kesar Milk Chocolate | U15: 3 | X15: Global Cocoa | Y15: 269993
A16: P033 | B16: Milk Chocolate Coins | C16: Cookies | D16: 114 | E16: 39 | F16: 44 | G16: 109 | H16: 13 | I16: ABC Traders | J16: =G16*H16 -> 1417 | K16: =D16+G16/2 -> 168.5 | L16: =F16/K16 -> 0.2611276 | M16: {=_xlfn.IFS(G16<50,"Low Stock",G16<100,"Medium Stock",G16>=100,"Healthy Stock")} -> Healthy Stock | N16: =G16*H16 -> 1417 | Q16: Grand Total | R16: 200 | T16: Caramel Crunch Cubes | U16: 3 | X16: Premium Foods | Y16: 264530
A17: P010 | B17: Dry Fruit Special Chocolate | C17: Bars | D17: 95 | E17: 114 | F17: 98 | G17: 111 | H17: 94 | I17: Choco World | J17: =G17*H17 -> 10434 | K17: =D17+G17/2 -> 150.5 | L17: =F17/K17 -> 0.65116279 | M17: {=_xlfn.IFS(G17<50,"Low Stock",G17<100,"Medium Stock",G17>=100,"Healthy Stock")} -> Healthy Stock | N17: =G17*H17 -> 10434 | T17: Dry Fruit Special Chocolate | U17: 3 | X17: Sweet Supplies | Y17: 242674
A18: P005 | B18: Choco Dip Cookie | C18: Premium | D18: 153 | E18: 145 | F18: 117 | G18: 181 | H18: 40 | I18: Choco World | J18: =G18*H18 -> 7240 | K18: =D18+G18/2 -> 243.5 | L18: =F18/K18 -> 0.48049281 | M18: {=_xlfn.IFS(G18<50,"Low Stock",G18<100,"Medium Stock",G18>=100,"Healthy Stock")} -> Healthy Stock | N18: =G18*H18 -> 7240 | T18: Duo Choco Bites | U18: 3 | X18: Grand Total | Y18: 1306080
A19: P028 | B19: Butterscotch Crunch Bar | C19: Bars | D19: 176 | E19: 21 | F19: 127 | G19: 70 | H19: 54 | I19: Sweet Supplies | J19: =G19*H19 -> 3780 | K19: =D19+G19/2 -> 211 | L19: =F19/K19 -> 0.60189573 | M19: {=_xlfn.IFS(G19<50,"Low Stock",G19<100,"Medium Stock",G19>=100,"Healthy Stock")} -> Medium Stock | N19: =G19*H19 -> 3780 | T19: Almond Crunch Bar | U19: 2
A20: P008 | B20: Hazelnut Praline Chocolate | C20: Premium | D20: 141 | E20: 109 | F20: 137 | G20: 113 | H20: 46 | I20: Sweet Supplies | J20: =G20*H20 -> 5198 | K20: =D20+G20/2 -> 197.5 | L20: =F20/K20 -> 0.69367089 | M20: {=_xlfn.IFS(G20<50,"Low Stock",G20<100,"Medium Stock",G20>=100,"Healthy Stock")} -> Healthy Stock | N20: =G20*H20 -> 5198 | T20: Nutella Filled Bites | U20: 2
A21: P012 | B21: Cashew Delight Bites | C21: Cookies | D21: 136 | E21: 85 | F21: 168 | G21: 53 | H21: 76 | I21: Premium Foods | J21: =G21*H21 -> 4028 | K21: =D21+G21/2 -> 162.5 | L21: =F21/K21 -> 1.0338462 | M21: {=_xlfn.IFS(G21<50,"Low Stock",G21<100,"Medium Stock",G21>=100,"Healthy Stock")} -> Medium Stock | N21: =G21*H21 -> 4028 | T21: Classic Dark Chocolate | U21: 2
A22: P035 | B22: Velvet Truffle Bites | C22: Cookies | D22: 50 | E22: 77 | F22: 70 | G22: 57 | H22: 106 | I22: Sweet Supplies | J22: =G22*H22 -> 6042 | K22: =D22+G22/2 -> 78.5 | L22: =F22/K22 -> 0.89171975 | M22: {=_xlfn.IFS(G22<50,"Low Stock",G22<100,"Medium Stock",G22>=100,"Healthy Stock")} -> Medium Stock | N22: =G22*H22 -> 6042 | T22: Festive Chocolate Pack | U22: 2
A23: P033 | B23: Milk Chocolate Coins | C23: Cookies | D23: 125 | E23: 46 | F23: 79 | G23: 92 | H23: 13 | I23: Choco World | J23: =G23*H23 -> 1196 | K23: =D23+G23/2 -> 171 | L23: =F23/K23 -> 0.4619883 | M23: {=_xlfn.IFS(G23<50,"Low Stock",G23<100,"Medium Stock",G23>=100,"Healthy Stock")} -> Medium Stock | N23: =G23*H23 -> 1196 | T23: Grand Total | U23: 56
A24: P002 | B24: Kunafa Bites | C24: Premium | D24: 121 | E24: 24 | F24: 176 | G24: -31 | H24: 96 | I24: ABC Traders | J24: =G24*H24 -> -2976 | K24: =D24+G24/2 -> 105.5 | L24: =F24/K24 -> 1.6682464 | M24: {=_xlfn.IFS(G24<50,"Low Stock",G24<100,"Medium Stock",G24>=100,"Healthy Stock")} -> Low Stock | N24: =G24*H24 -> -2976
A25: P028 | B25: Butterscotch Crunch Bar | C25: Bars | D25: 111 | E25: 110 | F25: 131 | G25: 90 | H25: 54 | I25: Premium Foods | J25: =G25*H25 -> 4860 | K25: =D25+G25/2 -> 156 | L25: =F25/K25 -> 0.83974359 | M25: {=_xlfn.IFS(G25<50,"Low Stock",G25<100,"Medium Stock",G25>=100,"Healthy Stock")} -> Medium Stock | N25: =G25*H25 -> 4860
A26: P028 | B26: Butterscotch Crunch Bar | C26: Bars | D26: 171 | E26: 36 | F26: 52 | G26: 155 | H26: 54 | I26: Premium Foods | J26: =G26*H26 -> 8370 | K26: =D26+G26/2 -> 248.5 | L26: =F26/K26 -> 0.20925553 | M26: {=_xlfn.IFS(G26<50,"Low Stock",G26<100,"Medium Stock",G26>=100,"Healthy Stock")} -> Healthy Stock | N26: =G26*H26 -> 8370
A27: P039 | B27: Luxury Praline Box | C27: Festive | D27: 126 | E27: 145 | F27: 33 | G27: 238 | H27: 118 | I27: Global Cocoa | J27: =G27*H27 -> 28084 | K27: =D27+G27/2 -> 245 | L27: =F27/K27 -> 0.13469388 | M27: {=_xlfn.IFS(G27<50,"Low Stock",G27<100,"Medium Stock",G27>=100,"Healthy Stock")} -> Healthy Stock | N27: =G27*H27 -> 28084
A28: P006 | B28: Love Loaded Chocolate Bar | C28: Festive | D28: 111 | E28: 117 | F28: 60 | G28: 168 | H28: 42 | I28: Premium Foods | J28: =G28*H28 -> 7056 | K28: =D28+G28/2 -> 195 | L28: =F28/K28 -> 0.30769231 | M28: {=_xlfn.IFS(G28<50,"Low Stock",G28<100,"Medium Stock",G28>=100,"Healthy Stock")} -> Healthy Stock | N28: =G28*H28 -> 7056
A29: P035 | B29: Velvet Truffle Bites | C29: Cookies | D29: 181 | E29: 108 | F29: 31 | G29: 258 | H29: 106 | I29: Sweet Supplies | J29: =G29*H29 -> 27348 | K29: =D29+G29/2 -> 310 | L29: =F29/K29 -> 0.1 | M29: {=_xlfn.IFS(G29<50,"Low Stock",G29<100,"Medium Stock",G29>=100,"Healthy Stock")} -> Healthy Stock | N29: =G29*H29 -> 27348
A30: P012 | B30: Cashew Delight Bites | C30: Cookies | D30: 163 | E30: 105 | F30: 88 | G30: 180 | H30: 76 | I30: Sweet Supplies | J30: =G30*H30 -> 13680 | K30: =D30+G30/2 -> 253 | L30: =F30/K30 -> 0.34782609 | M30: {=_xlfn.IFS(G30<50,"Low Stock",G30<100,"Medium Stock",G30>=100,"Healthy Stock")} -> Healthy Stock | N30: =G30*H30 -> 13680
A31: P028 | B31: Butterscotch Crunch Bar | C31: Bars | D31: 181 | E31: 116 | F31: 140 | G31: 157 | H31: 54 | I31: Global Cocoa | J31: =G31*H31 -> 8478 | K31: =D31+G31/2 -> 259.5 | L31: =F31/K31 -> 0.53949904 | M31: {=_xlfn.IFS(G31<50,"Low Stock",G31<100,"Medium Stock",G31>=100,"Healthy Stock")} -> Healthy Stock | N31: =G31*H31 -> 8478
A32: P031 | B32: Honey Almond Chocolate | C32: Cookies | D32: 150 | E32: 124 | F32: 114 | G32: 160 | H32: 72 | I32: Choco World | J32: =G32*H32 -> 11520 | K32: =D32+G32/2 -> 230 | L32: =F32/K32 -> 0.49565217 | M32: {=_xlfn.IFS(G32<50,"Low Stock",G32<100,"Medium Stock",G32>=100,"Healthy Stock")} -> Healthy Stock | N32: =G32*H32 -> 11520
A33: P020 | B33: Coffee Mocha Bites | C33: Snacks | D33: 109 | E33: 65 | F33: 46 | G33: 128 | H33: 10 | I33: Sweet Supplies | J33: =G33*H33 -> 1280 | K33: =D33+G33/2 -> 173 | L33: =F33/K33 -> 0.26589595 | M33: {=_xlfn.IFS(G33<50,"Low Stock",G33<100,"Medium Stock",G33>=100,"Healthy Stock")} -> Healthy Stock | N33: =G33*H33 -> 1280
A34: P003 | B34: Choco Crunch Cone | C34: Bars | D34: 178 | E34: 23 | F34: 102 | G34: 99 | H34: 66 | I34: Sweet Supplies | J34: =G34*H34 -> 6534 | K34: =D34+G34/2 -> 227.5 | L34: =F34/K34 -> 0.44835165 | M34: {=_xlfn.IFS(G34<50,"Low Stock",G34<100,"Medium Stock",G34>=100,"Healthy Stock")} -> Medium Stock | N34: =G34*H34 -> 6534
A35: P030 | B35: Royal Dryfruit Mix | C35: Cookies | D35: 142 | E35: 23 | F35: 57 | G35: 108 | H35: 55 | I35: Premium Foods | J35: =G35*H35 -> 5940 | K35: =D35+G35/2 -> 196 | L35: =F35/K35 -> 0.29081633 | M35: {=_xlfn.IFS(G35<50,"Low Stock",G35<100,"Medium Stock",G35>=100,"Healthy Stock")} -> Healthy Stock | N35: =G35*H35 -> 5940
... A201: P025 | B201: Berry Blast Chocolate | C201: Festive | D201: 96 | E201: 20 | F201: 82 | G201: 34 | H201: 113 | I201: Sweet Supplies | J201: =G201*H201 -> 3842 | K201: =D201+G201/2 -> 113 | L201: =F201/K201 -> 0.72566372 | M201: {=_xlfn.IFS(G201<50,"Low Stock",G201<100,"Medium Stock",G201>=100,"Healthy Stock")} -> Low Stock | N201: =G201*H201 -> 3842
J202: =G202*H202 -> 0

Sheet Dashboard
A1: =SUM(Sales_Data!J:J) -> 448372.15 | B1: =SUM(Sales_Data!M:M) -> 207956

Sheet Sales_Data
A1: Order_ID | B1: Order_Date | C1: Customer_Name | D1: Product_ID | E1: Product_Name | F1: Category | G1: Quantity_Sold | H1: Selling_Price | I1: Discount | J1: Total_Sales | K1: Region | L1: Month | M1: total profit | N1: margin | O1: turnover
A2: O0001 | B2: 2025-06-25 | C2: Arjun | D2: P013 | E2: Pistachio Fusion Chocolate | F2: Cookies | G2: 1 | H2: 143 | I2: 10 | J2: 128.7 | K2: Delhi | L2: =TEXT(B2,"mmm") -> Jun | M2: =(H2-_xlfn.XLOOKUP(D2,Product_Master!A:A,Product_Master!D:D))*G2 -> 42 | N2: =M2/J2 -> 0.32634033 | O2: =G2/Inventory!$G$2 -> 0.01754386 | V2: Region | W2: (All)
A3: O0002 | B3: 2025-04-21 | C3: Rahul | D3: P019 | E3: White Chocolate Truffle | F3: Bars | G3: 13 | H3: 95 | I3: 5 | J3: 1173.25 | K3: Mumbai | L3: =TEXT(B3,"mmm") -> Apr | M3: =(H3-_xlfn.XLOOKUP(D3,Product_Master!A:A,Product_Master!D:D))*G3 -> 962 | N3: =M3/J3 -> 0.8199446 | O3: =G3/Inventory!$G$2 -> 0.22807018
A4: O0003 | B4: 2025-02-06 | C4: Arjun | D4: P037 | E4: Golden Caramel Bites | F4: Snacks | G4: 11 | H4: 160 | I4: 0 | J4: 1760 | K4: Chennai | L4: =TEXT(B4,"mmm") -> Feb | M4: =(H4-_xlfn.XLOOKUP(D4,Product_Master!A:A,Product_Master!D:D))*G4 -> 605 | N4: =M4/J4 -> 0.34375 | O4: =G4/Inventory!$G$2 -> 0.19298246 | P4: Total Sales | R4: Row Labels | S4: sales | V4: Row Labels | W4: Sales | X4: profit | Y4: profit margin | AA4: Row Labels | AB4: Sales | AC4: profit
A5: O0004 | B5: 2025-01-31 | C5: Rohan | D5: P017 | E5: Kesar Milk Chocolate | F5: Cookies | G5: 1 | H5: 151 | I5: 0 | J5: 151 | K5: Delhi | L5: =TEXT(B5,"mmm") -> Jan | M5: =(H5-_xlfn.XLOOKUP(D5,Product_Master!A:A,Product_Master!D:D))*G5 -> 53 | N5: =M5/J5 -> 0.35099338 | O5: =G5/Inventory!$G$2 -> 0.01754386 | P5: 448372.15 | R5: Jan | S5: 88968.65 | V5: Bars | W5: 92694.5 | X5: 38332 | Y5: 44.597419 | AA5: Classic Dark Chocolate | AB5: 14052.9 | AC5: 7560
A6: O0005 | B6: 2025-04-07 | C6: Pooja | D6: P002 | E6: Kunafa Bites | F6: Premium | G6: 5 | H6: 146 | I6: 10 | J6: 657 | K6: Mumbai | L6: =TEXT(B6,"mmm") -> Apr | M6: =(H6-_xlfn.XLOOKUP(D6,Product_Master!A:A,Product_Master!D:D))*G6 -> 250 | N6: =M6/J6 -> 0.3805175 | O6: =G6/Inventory!$G$2 -> 0.087719298 | R6: Feb | S6: 62529.05 | V6: Cookies | W6: 121242.7 | X6: 58149 | Y6: 66.908831 | AA6: Pistachio Fusion Chocolate | AB6: 15429.7 | AC6: 4914
A7: O0006 | B7: 2025-04-26 | C7: Kiran | D7: P034 | E7: Signature Cocoa Bars | F7: Cookies | G7: 6 | H7: 154 | I7: 10 | J7: 831.6 | K7: Bangalore | L7: =TEXT(B7,"mmm") -> Apr | M7: =(H7-_xlfn.XLOOKUP(D7,Product_Master!A:A,Product_Master!D:D))*G7 -> 348 | N7: =M7/J7 -> 0.41847042 | O7: =G7/Inventory!$G$2 -> 0.10526316 | P7: Total Profit | R7: Mar | S7: 83526.35 | V7: Festive | W7: 107131.8 | X7: 53299 | Y7: 49.054799 | AA7: Royal Dryfruit Mix | AB7: 15889.5 | AC7: 10160
A8: O0007 | B8: 2025-02-19 | C8: Rohan | D8: P036 | E8: Classic Dark Chocolate | F8: Cookies | G8: 15 | H8: 139 | I8: 0 | J8: 2085 | K8: Bangalore | L8: =TEXT(B8,"mmm") -> Feb | M8: =(H8-_xlfn.XLOOKUP(D8,Product_Master!A:A,Product_Master!D:D))*G8 -> 1050 | N8: =M8/J8 -> 0.50359712 | O8: =G8/Inventory!$G$2 -> 0.26315789 | P8: 207956 | R8: Apr | S8: 81735.7 | V8: Premium | W8: 60312.2 | X8: 25410 | Y8: 34.175014 | AA8: Dry Fruit Special Chocolate | AB8: 16920 | AC8: 7656
A9: O0008 | B9: 2025-04-15 | C9: Sneha | D9: P017 | E9: Kesar Milk Chocolate | F9: Cookies | G9: 4 | H9: 151 | I9: 15 | J9: 513.4 | K9: Pune | L9: =TEXT(B9,"mmm") -> Apr | M9: =(H9-_xlfn.XLOOKUP(D9,Product_Master!A:A,Product_Master!D:D))*G9 -> 212 | N9: =M9/J9 -> 0.41293339 | O9: =G9/Inventory!$G$2 -> 0.070175439 | R9: May | S9: 66014.35 | V9: Snacks | W9: 66990.95 | X9: 32766 | Y9: 45.132236 | AA9: Festive Chocolate Pack | AB9: 17262.25 | AC9: 10496
A10: O0009 | B10: 2025-03-10 | C10: Vikas | D10: P013 | E10: Pistachio Fusion Chocolate | F10: Cookies | G10: 7 | H10: 143 | I10: 0 | J10: 1001 | K10: Bangalore | L10: =TEXT(B10,"mmm") -> Mar | M10: =(H10-_xlfn.XLOOKUP(D10,Product_Master!A:A,Product_Master!D:D))*G10 -> 294 | N10: =M10/J10 -> 0.29370629 | O10: =G10/Inventory!$G$2 -> 0.12280702 | P10: Profit Margin | R10: Jun | S10: 65598.05 | V10: Grand Total | W10: 448372.15 | X10: 207956 | Y10: 239.8683 | AA10: Velvet Truffle Bites | AB10: 17760.75 | AC10: 8928
A11: O0010 | B11: 2025-02-01 | C11: Anjali | D11: P022 | E11: Mint Choco Squares | F11: Festive | G11: 11 | H11: 147 | I11: 10 | J11: 1455.3 | K11: Pune | L11: =TEXT(B11,"mmm") -> Feb | M11: =(H11-_xlfn.XLOOKUP(D11,Product_Master!A:A,Product_Master!D:D))*G11 -> 946 | N11: =M11/J11 -> 0.65003779 | O11: =G11/Inventory!$G$2 -> 0.19298246 | P11: =(P8/P5) -> 0.46380222 | R11: Grand Total | S11: 448372.15 | AA11: Berry Blast Chocolate | AB11: 18505.2 | AC11: 6380
A12: O0011 | B12: 2025-05-27 | C12: Kiran | D12: P016 | E12: Nutella Filled Bites | F12: Cookies | G12: 14 | H12: 89 | I12: 0 | J12: 1246 | K12: Bangalore | L12: =TEXT(B12,"mmm") -> May | M12: =(H12-_xlfn.XLOOKUP(D12,Product_Master!A:A,Product_Master!D:D))*G12 -> 910 | N12: =M12/J12 -> 0.73033708 | O12: =G12/Inventory!$G$2 -> 0.24561404 | U12: Row Labels | V12: Sales | W12: profit | X12: profit margin | AA12: Premium Cocoa Slabs | AB12: 19210.5 | AC12: 6407
A13: O0012 | B13: 2025-01-28 | C13: Anjali | D13: P017 | E13: Kesar Milk Chocolate | F13: Cookies | G13: 2 | H13: 151 | I13: 5 | J13: 286.9 | K13: Pune | L13: =TEXT(B13,"mmm") -> Jan | M13: =(H13-_xlfn.XLOOKUP(D13,Product_Master!A:A,Product_Master!D:D))*G13 -> 106 | N13: =M13/J13 -> 0.36946671 | O13: =G13/Inventory!$G$2 -> 0.035087719 | R13: Row Labels | S13: Sales | U13: 0 | V13: 136454 | W13: 58870 | X13: 56.235858 | AA13: Luxury Praline Box | AB13: 20000.5 | AC13: 7497 | AE13: Region | AF13: Sales | AG13: profit | AH13: profit margin
A14: O0013 | B14: 2025-04-13 | C14: Sneha | D14: P002 | E14: Kunafa Bites | F14: Premium | G14: 8 | H14: 146 | I14: 15 | J14: 992.8 | K14: Mumbai | L14: =TEXT(B14,"mmm") -> Apr | M14: =(H14-_xlfn.XLOOKUP(D14,Product_Master!A:A,Product_Master!D:D))*G14 -> 400 | N14: =M14/J14 -> 0.40290089 | O14: =G14/Inventory!$G$2 -> 0.14035088 | P14: Total Order | R14: Bangalore | S14: 82119.8 | U14: 5 | V14: 118280.7 | W14: 53029 | X14: 63.315566 | AA14: Fruit & Nut Chocolate | AB14: 22253.4 | AC14: 9639 | AE14: Bangalore | AF14: 82119.8 | AG14: 39144 | AH14: 0.1792087
A15: O0014 | B15: 2025-01-17 | C15: Vikas | D15: P039 | E15: Luxury Praline Box | F15: Festive | G15: 11 | H15: 181 | I15: 5 | J15: 1891.45 | K15: Pune | L15: =TEXT(B15,"mmm") -> Jan | M15: =(H15-_xlfn.XLOOKUP(D15,Product_Master!A:A,Product_Master!D:D))*G15 -> 693 | N15: =M15/J15 -> 0.36638558 | O15: =G15/Inventory!$G$2 -> 0.19298246 | P15: 500 | R15: Chennai | S15: 80975.7 | U15: 10 | V15: 99186.3 | W15: 48498 | X15: 53.169603 | AA15: Grand Total | AB15: 177284.7 | AC15: 79637 | AE15: Chennai | AF15: 80975.7 | AG15: 36871 | AH15: 0.16632487
A16: O0015 | B16: 2025-01-09 | C16: Kiran | D16: P003 | E16: Choco Crunch Cone | F16: Bars | G16: 1 | H16: 86 | I16: 5 | J16: 81.7 | K16: Bangalore | L16: =TEXT(B16,"mmm") -> Jan | M16: =(H16-_xlfn.XLOOKUP(D16,Product_Master!A:A,Product_Master!D:D))*G16 -> 20 | N16: =M16/J16 -> 0.24479804 | O16: =G16/Inventory!$G$2 -> 0.01754386 | R16: Delhi | S16: 73435.1 | U16: 15 | V16: 94451.15 | W16: 47559 | X16: 67.147273 | AE16: Delhi | AF16: 73435.1 | AG16: 35183 | AH16: 0.17134229
A17: O0016 | B17: 2025-06-11 | C17: Rahul | D17: P015 | E17: Caramel Crunch Cubes | F17: Festive | G17: 7 | H17: 158 | I17: 0 | J17: 1106 | K17: Chennai | L17: =TEXT(B17,"mmm") -> Jun | M17: =(H17-_xlfn.XLOOKUP(D17,Product_Master!A:A,Product_Master!D:D))*G17 -> 665 | N17: =M17/J17 -> 0.60126582 | O17: =G17/Inventory!$G$2 -> 0.12280702 | P17: Total Quantity Sold | R17: Hyderabad | S17: 68341.9 | U17: Grand Total | V17: 448372.15 | W17: 207956 | X17: 239.8683 | AE17: Hyderabad | AF17: 68341.9 | AG17: 31757 | AH17: 0.15776581
A18: O0017 | B18: 2025-04-29 | C18: Pooja | D18: P040 | E18: Festive Chocolate Pack | F18: Festive | G18: 11 | H18: 145 | I18: 10 | J18: 1435.5 | K18: Hyderabad | L18: =TEXT(B18,"mmm") -> Apr | M18: =(H18-_xlfn.XLOOKUP(D18,Product_Master!A:A,Product_Master!D:D))*G18 -> 902 | N18: =M18/J18 -> 0.62835249 | O18: =G18/Inventory!$G$2 -> 0.19298246 | P18: 4033 | R18: Mumbai | S18: 67032.8 | AA18: Customer Name | AB18: Sales | AC18: profit | AE18: Mumbai | AF18: 67032.8 | AG18: 29649 | AH18: 0.1590273
A19: O0018 | B19: 2025-06-06 | C19: Priya | D19: P011 | E19: Almond Crunch Bar | F19: Bars | G19: 2 | H19: 90 | I19: 5 | J19: 171 | K19: Bangalore | L19: =TEXT(B19,"mmm") -> Jun | M19: =(H19-_xlfn.XLOOKUP(D19,Product_Master!A:A,Product_Master!D:D))*G19 -> 62 | N19: =M19/J19 -> 0.3625731 | O19: =G19/Inventory!$G$2 -> 0.035087719 | R19: Pune | S19: 76466.85 | U19: Row Labels | V19: Sum of turnover | X19: Row Labels | Y19: Sum of turnover | AA19: Anjali | AB19: 53665.75 | AC19: 24972 | AE19: Pune | AF19: 76466.85 | AG19: 35352 | AH19: 0.16633103
A20: O0019 | B20: 2025-05-25 | C20: Vikas | D20: P034 | E20: Signature Cocoa Bars | F20: Cookies | G20: 9 | H20: 154 | I20: 5 | J20: 1316.7 | K20: Bangalore | L20: =TEXT(B20,"mmm") -> May | M20: =(H20-_xlfn.XLOOKUP(D20,Product_Master!A:A,Product_Master!D:D))*G20 -> 522 | N20: =M20/J20 -> 0.39644566 | O20: =G20/Inventory!$G$2 -> 0.15789474 | P20: Avg. Order value | R20: Grand Total | S20: 448372.15 | U20: Silk Ganache Cubes | V20: 2.2982456 | X20: Honey Almond Chocolate | Y20: 1.1578947 | AA20: Pooja | AB20: 44119.75 | AC20: 19332 | AE20: Grand Total | AF20: 448372.15 | AG20: 207956 | AH20: 1
A21: O0020 | B21: 2025-05-24 | C21: Vikas | D21: P022 | E21: Mint Choco Squares | F21: Festive | G21: 15 | H21: 147 | I21: 10 | J21: 1984.5 | K21: Delhi | L21: =TEXT(B21,"mmm") -> May | M21: =(H21-_xlfn.XLOOKUP(D21,Product_Master!A:A,Product_Master!D:D))*G21 -> 1290 | N21: =M21/J21 -> 0.65003779 | O21: =G21/Inventory!$G$2 -> 0.26315789 | P21: 896.7443 | U21: Cashew Delight Bites | V21: 2.5789474 | X21: Butterscotch Crunch Bar | Y21: 1.1403509 | AA21: Arjun | AB21: 40442.9 | AC21: 19651
A22: O0021 | B22: 2025-06-20 | C22: Amit | D22: P018 | E22: Fruit & Nut Chocolate | F22: Snacks | G22: 3 | H22: 156 | I22: 0 | J22: 468 | K22: Pune | L22: =TEXT(B22,"mmm") -> Jun | M22: =(H22-_xlfn.XLOOKUP(D22,Product_Master!A:A,Product_Master!D:D))*G22 -> 189 | N22: =M22/J22 -> 0.40384615 | O22: =G22/Inventory!$G$2 -> 0.052631579 | U22: Choco Crunch Cone | V22: 2.5789474 | X22: Love Loaded Chocolate Bar | Y22: 1.0701754 | AA22: Vikas | AB22: 40351.95 | AC22: 18321
A23: O0022 | B23: 2025-04-26 | C23: Sneha | D23: P035 | E23: Velvet Truffle Bites | F23: Cookies | G23: 1 | H23: 199 | I23: 0 | J23: 199 | K23: Chennai | L23: =TEXT(B23,"mmm") -> Apr | M23: =(H23-_xlfn.XLOOKUP(D23,Product_Master!A:A,Product_Master!D:D))*G23 -> 93 | N23: =M23/J23 -> 0.46733668 | O23: =G23/Inventory!$G$2 -> 0.01754386 | P23: Inventory value | U23: Premium Cocoa Slabs | V23: 2.6140351 | X23: Choco Pie Popstick | Y23: 1.0350877 | AA23: Priya | AB23: 37369.95 | AC23: 17159
A24: O0023 | B24: 2025-03-29 | C24: Priya | D24: P007 | E24: Choco Aura Custom Bar | F24: Premium | G24: 7 | H24: 128 | I24: 0 | J24: 896 | K24: Bangalore | L24: =TEXT(B24,"mmm") -> Mar | M24: =(H24-_xlfn.XLOOKUP(D24,Product_Master!A:A,Product_Master!D:D))*G24 -> 371 | N24: =M24/J24 -> 0.4140625 | O24: =G24/Inventory!$G$2 -> 0.12280702 | P24: 1306080 | U24: Fruit & Nut Chocolate | V24: 2.6842105 | X24: Choco Dip Cookie | Y24: 0.73684211 | AA24: Neha | AB24: 36876.35 | AC24: 17444
A25: O0024 | B25: 2025-03-30 | C25: Anjali | D25: P012 | E25: Cashew Delight Bites | F25: Cookies | G25: 14 | H25: 98 | I25: 5 | J25: 1303.4 | K25: Pune | L25: =TEXT(B25,"mmm") -> Mar | M25: =(H25-_xlfn.XLOOKUP(D25,Product_Master!A:A,Product_Master!D:D))*G25 -> 308 | N25: =M25/J25 -> 0.23630505 | O25: =G25/Inventory!$G$2 -> 0.24561404 | U25: Grand Total | V25: 12.754386 | X25: Grand Total | Y25: 5.1403509 | AA25: Meera | AB25: 36205.95 | AC25: 15802
A26: O0025 | B26: 2025-02-22 | C26: Amit | D26: P012 | E26: Cashew Delight Bites | F26: Cookies | G26: 11 | H26: 98 | I26: 15 | J26: 916.3 | K26: Chennai | L26: =TEXT(B26,"mmm") -> Feb | M26: =(H26-_xlfn.XLOOKUP(D26,Product_Master!A:A,Product_Master!D:D))*G26 -> 242 | N26: =M26/J26 -> 0.26410564 | O26: =G26/Inventory!$G$2 -> 0.19298246 | P26: Inventory Turnover | AA26: Sneha | AB26: 35636 | AC26: 16179
A27: O0026 | B27: 2025-06-30 | C27: Rohan | D27: P010 | E27: Dry Fruit Special Chocolate | F27: Bars | G27: 6 | H27: 160 | I27: 15 | J27: 816 | K27: Chennai | L27: =TEXT(B27,"mmm") -> Jun | M27: =(H27-_xlfn.XLOOKUP(D27,Product_Master!A:A,Product_Master!D:D))*G27 -> 396 | N27: =M27/J27 -> 0.48529412 | O27: =G27/Inventory!$G$2 -> 0.10526316 | P27: 179.77847 | AA27: Rohan | AB27: 33594.95 | AC27: 16137
A28: O0027 | B28: 2025-05-02 | C28: Pooja | D28: P025 | E28: Berry Blast Chocolate | F28: Festive | G28: 9 | H28: 168 | I28: 10 | J28: 1360.8 | K28: Mumbai | L28: =TEXT(B28,"mmm") -> May | M28: =(H28-_xlfn.XLOOKUP(D28,Product_Master!A:A,Product_Master!D:D))*G28 -> 495 | N28: =M28/J28 -> 0.36375661 | O28: =G28/Inventory!$G$2 -> 0.15789474 | AA28: Rahul | AB28: 33123.85 | AC28: 15429
A29: O0028 | B29: 2025-03-21 | C29: Vikas | D29: P017 | E29: Kesar Milk Chocolate | F29: Cookies | G29: 3 | H29: 151 | I29: 0 | J29: 453 | K29: Bangalore | L29: =TEXT(B29,"mmm") -> Mar | M29: =(H29-_xlfn.XLOOKUP(D29,Product_Master!A:A,Product_Master!D:D))*G29 -> 159 | N29: =M29/J29 -> 0.35099338 | O29: =G29/Inventory!$G$2 -> 0.052631579 | AA29: Grand Total | AB29: 391387.4 | AC29: 180426
A30: O0029 | B30: 2025-02-08 | C30: Neha | D30: P026 | E30: Silk Ganache Cubes | F30: Festive | G30: 2 | H30: 82 | I30: 5 | J30: 155.8 | K30: Chennai | L30: =TEXT(B30,"mmm") -> Feb | M30: =(H30-_xlfn.XLOOKUP(D30,Product_Master!A:A,Product_Master!D:D))*G30 -> 80 | N30: =M30/J30 -> 0.51347882 | O30: =G30/Inventory!$G$2 -> 0.035087719 | R30: Row Labels | S30: sales
A31: O0030 | B31: 2025-03-18 | C31: Priya | D31: P001 | E31: Choco Pie Popstick | F31: Snacks | G31: 10 | H31: 74 | I31: 0 | J31: 740 | K31: Pune | L31: =TEXT(B31,"mmm") -> Mar | M31: =(H31-_xlfn.XLOOKUP(D31,Product_Master!A:A,Product_Master!D:D))*G31 -> 280 | N31: =M31/J31 -> 0.37837838 | O31: =G31/Inventory!$G$2 -> 0.1754386 | R31: Jan | S31: 88968.65
A32: O0031 | B32: 2025-04-25 | C32: Amit | D32: P018 | E32: Fruit & Nut Chocolate | F32: Snacks | G32: 4 | H32: 156 | I32: 5 | J32: 592.8 | K32: Chennai | L32: =TEXT(B32,"mmm") -> Apr | M32: =(H32-_xlfn.XLOOKUP(D32,Product_Master!A:A,Product_Master!D:D))*G32 -> 252 | N32: =M32/J32 -> 0.42510121 | O32: =G32/Inventory!$G$2 -> 0.070175439 | R32: Feb | S32: 62529.05
A33: O0032 | B33: 2025-03-22 | C33: Neha | D33: P004 | E33: Duo Choco Bites | F33: Bars | G33: 4 | H33: 99 | I33: 10 | J33: 356.4 | K33: Pune | L33: =TEXT(B33,"mmm") -> Mar | M33: =(H33-_xlfn.XLOOKUP(D33,Product_Master!A:A,Product_Master!D:D))*G33 -> 96 | N33: =M33/J33 -> 0.26936027 | O33: =G33/Inventory!$G$2 -> 0.070175439 | R33: Mar | S33: 83526.35
A34: O0033 | B34: 2025-05-25 | C34: Meera | D34: P008 | E34: Hazelnut Praline Chocolate | F34: Premium | G34: 6 | H34: 76 | I34: 15 | J34: 387.6 | K34: Delhi | L34: =TEXT(B34,"mmm") -> May | M34: =(H34-_xlfn.XLOOKUP(D34,Product_Master!A:A,Product_Master!D:D))*G34 -> 180 | N34: =M34/J34 -> 0.46439628 | O34: =G34/Inventory!$G$2 -> 0.10526316 | R34: Apr | S34: 81735.7
A35: O0034 | B35: 2025-04-21 | C35: Arjun | D35: P039 | E35: Luxury Praline Box | F35: Festive | G35: 4 | H35: 181 | I35: 5 | J35: 687.8 | K35: Pune | L35: =TEXT(B35,"mmm") -> Apr | M35: =(H35-_xlfn.XLOOKUP(D35,Product_Master!A:A,Product_Master!D:D))*G35 -> 252 | N35: =M35/J35 -> 0.36638558 | O35: =G35/Inventory!$G$2 -> 0.070175439 | R35: May | S35: 66014.35
A36: O0035 | B36: 2025-01-21 | C36: Kiran | D36: P004 | E36: Duo Choco Bites | F36: Bars | G36: 13 | H36: 99 | I36: 15 | J36: 1093.95 | K36: Hyderabad | L36: =TEXT(B36,"mmm") -> Jan | M36: =(H36-_xlfn.XLOOKUP(D36,Product_Master!A:A,Product_Master!D:D))*G36 -> 312 | N36: =M36/J36 -> 0.28520499 | O36: =G36/Inventory!$G$2 -> 0.22807018 | R36: Jun | S36: 65598.05
A37: O0036 | B37: 2025-02-13 | C37: Rahul | D37: P009 | E37: Rose Pista Chocolate | F37: Festive | G37: 15 | H37: 96 | I37: 5 | J37: 1368 | K37: Bangalore | L37: =TEXT(B37,"mmm") -> Feb | M37: =(H37-_xlfn.XLOOKUP(D37,Product_Master!A:A,Product_Master!D:D))*G37 -> 360 | N37: =M37/J37 -> 0.26315789 | O37: =G37/Inventory!$G$2 -> 0.26315789 | R37: Grand Total | S37: 448372.15
A38: O0037 | B38: 2025-05-07 | C38: Neha | D38: P032 | E38: Choco Fudge Squares | F38: Premium | G38: 6 | H38: 130 | I38: 5 | J38: 741 | K38: Mumbai | L38: =TEXT(B38,"mmm") -> May | M38: =(H38-_xlfn.XLOOKUP(D38,Product_Master!A:A,Product_Master!D:D))*G38 -> 270 | N38: =M38/J38 -> 0.36437247 | O38: =G38/Inventory!$G$2 -> 0.10526316
A39: O0038 | B39: 2025-03-29 | C39: Priya | D39: P011 | E39: Almond Crunch Bar | F39: Bars | G39: 6 | H39: 90 | I39: 15 | J39: 459 | K39: Chennai | L39: =TEXT(B39,"mmm") -> Mar | M39: =(H39-_xlfn.XLOOKUP(D39,Product_Master!A:A,Product_Master!D:D))*G39 -> 186 | N39: =M39/J39 -> 0.40522876 | O39: =G39/Inventory!$G$2 -> 0.10526316
A40: O0039 | B40: 2025-03-08 | C40: Anjali | D40: P006 | E40: Love Loaded Chocolate Bar | F40: Festive | G40: 8 | H40: 140 | I40: 10 | J40: 1008 | K40: Mumbai | L40: =TEXT(B40,"mmm") -> Mar | M40: =(H40-_xlfn.XLOOKUP(D40,Product_Master!A:A,Product_Master!D:D))*G40 -> 784 | N40: =M40/J40 -> 0.77777778 | O40: =G40/Inventory!$G$2 -> 0.14035088
...
